Traceback (most recent call last):
  File "/home/bcaffo/miniconda3/envs/ds4bio/lib/python3.9/site-packages/jupyter_cache/executors/utils.py", line 51, in single_nb_execution
    executenb(
  File "/home/bcaffo/miniconda3/envs/ds4bio/lib/python3.9/site-packages/nbclient/client.py", line 1117, in execute
    return NotebookClient(nb=nb, resources=resources, km=km, **kwargs).execute()
  File "/home/bcaffo/miniconda3/envs/ds4bio/lib/python3.9/site-packages/nbclient/util.py", line 78, in wrapped
    return just_run(coro(*args, **kwargs))
  File "/home/bcaffo/miniconda3/envs/ds4bio/lib/python3.9/site-packages/nbclient/util.py", line 57, in just_run
    return loop.run_until_complete(coro)
  File "/home/bcaffo/miniconda3/envs/ds4bio/lib/python3.9/asyncio/base_events.py", line 642, in run_until_complete
    return future.result()
  File "/home/bcaffo/miniconda3/envs/ds4bio/lib/python3.9/site-packages/nbclient/client.py", line 558, in async_execute
    await self.async_execute_cell(
  File "/home/bcaffo/miniconda3/envs/ds4bio/lib/python3.9/site-packages/nbclient/client.py", line 862, in async_execute_cell
    self._check_raise_for_error(cell, exec_reply)
  File "/home/bcaffo/miniconda3/envs/ds4bio/lib/python3.9/site-packages/nbclient/client.py", line 765, in _check_raise_for_error
    raise CellExecutionError.from_cell_and_msg(cell, exec_reply_content)
nbclient.exceptions.CellExecutionError: An error occurred while executing the following cell:
------------------
y1 = dat.PD
x1 = np.zeros(y.size) + 1
x2 = dat.FLAIR
x3 = dat.T1

def resid(x, y):
  return y - x * np.sum(x * y) / np.sum(x ** 2)

## Regress x1 out of everything
ey1x1 = resid(x1, y1)
ex2x1 = resid(x1, x2)
ex3x1 = resid(x1, x3)

## Regress the residual for x2 out of everything
ey1x1x2 = resid(ex2x1, ey1x1)
ex3x1x2 = resid(ex2x1, ex3x1)


np.sum(ex3x1x2 * ey1x1x2) / np.sum(ex3x1x2 ** 2)


------------------

[0;31m---------------------------------------------------------------------------[0m
[0;31mNameError[0m                                 Traceback (most recent call last)
[0;32m/tmp/ipykernel_11886/2071228802.py[0m in [0;36m<module>[0;34m[0m
[1;32m      1[0m [0my1[0m [0;34m=[0m [0mdat[0m[0;34m.[0m[0mPD[0m[0;34m[0m[0;34m[0m[0m
[0;32m----> 2[0;31m [0mx1[0m [0;34m=[0m [0mnp[0m[0;34m.[0m[0mzeros[0m[0;34m([0m[0my[0m[0;34m.[0m[0msize[0m[0;34m)[0m [0;34m+[0m [0;36m1[0m[0;34m[0m[0;34m[0m[0m
[0m[1;32m      3[0m [0mx2[0m [0;34m=[0m [0mdat[0m[0;34m.[0m[0mFLAIR[0m[0;34m[0m[0;34m[0m[0m
[1;32m      4[0m [0mx3[0m [0;34m=[0m [0mdat[0m[0;34m.[0m[0mT1[0m[0;34m[0m[0;34m[0m[0m
[1;32m      5[0m [0;34m[0m[0m

[0;31mNameError[0m: name 'y' is not defined
NameError: name 'y' is not defined

