Traceback (most recent call last):
  File "/home/bcaffo/miniconda3/envs/ds4bio/lib/python3.9/site-packages/jupyter_cache/executors/utils.py", line 51, in single_nb_execution
    executenb(
  File "/home/bcaffo/miniconda3/envs/ds4bio/lib/python3.9/site-packages/nbclient/client.py", line 1112, in execute
    return NotebookClient(nb=nb, resources=resources, km=km, **kwargs).execute()
  File "/home/bcaffo/miniconda3/envs/ds4bio/lib/python3.9/site-packages/nbclient/util.py", line 74, in wrapped
    return just_run(coro(*args, **kwargs))
  File "/home/bcaffo/miniconda3/envs/ds4bio/lib/python3.9/site-packages/nbclient/util.py", line 53, in just_run
    return loop.run_until_complete(coro)
  File "/home/bcaffo/miniconda3/envs/ds4bio/lib/python3.9/asyncio/base_events.py", line 642, in run_until_complete
    return future.result()
  File "/home/bcaffo/miniconda3/envs/ds4bio/lib/python3.9/site-packages/nbclient/client.py", line 553, in async_execute
    await self.async_execute_cell(
  File "/home/bcaffo/miniconda3/envs/ds4bio/lib/python3.9/site-packages/nbclient/client.py", line 857, in async_execute_cell
    self._check_raise_for_error(cell, exec_reply)
  File "/home/bcaffo/miniconda3/envs/ds4bio/lib/python3.9/site-packages/nbclient/client.py", line 760, in _check_raise_for_error
    raise CellExecutionError.from_cell_and_msg(cell, exec_reply_content)
nbclient.exceptions.CellExecutionError: An error occurred while executing the following cell:
------------------
import pandas as pd
import torch
import statsmodels.formula.api as smf
import statsmodels as sm
import seaborn as sns
import matplotlib.pyplot as plt
import numpy as np

## Read in the data and display a few rows
dat = pd.read_csv("https://raw.githubusercontent.com/bcaffo/ds4bme_intro/master/data/oasis.csv")
dat.head(4)

## Create a binary outcome variable (people will use gold lesions in HW)
m = np.median(dat.T2)
dat = dat.assign(y = (dat.T2 > m) * 1 )
## Create a normalized regression variable
dat = dat.assign(x = (dat.PD - np.mean(dat.PD)) / np.std(dat.PD))
dat.head()

------------------

[0;31m---------------------------------------------------------------------------[0m
[0;31mModuleNotFoundError[0m                       Traceback (most recent call last)
[0;32m/tmp/ipykernel_14235/3040608148.py[0m in [0;36m<module>[0;34m[0m
[1;32m      1[0m [0;32mimport[0m [0mpandas[0m [0;32mas[0m [0mpd[0m[0;34m[0m[0;34m[0m[0m
[1;32m      2[0m [0;32mimport[0m [0mtorch[0m[0;34m[0m[0;34m[0m[0m
[0;32m----> 3[0;31m [0;32mimport[0m [0mstatsmodels[0m[0;34m.[0m[0mformula[0m[0;34m.[0m[0mapi[0m [0;32mas[0m [0msmf[0m[0;34m[0m[0;34m[0m[0m
[0m[1;32m      4[0m [0;32mimport[0m [0mstatsmodels[0m [0;32mas[0m [0msm[0m[0;34m[0m[0;34m[0m[0m
[1;32m      5[0m [0;32mimport[0m [0mseaborn[0m [0;32mas[0m [0msns[0m[0;34m[0m[0;34m[0m[0m

[0;31mModuleNotFoundError[0m: No module named 'statsmodels'
ModuleNotFoundError: No module named 'statsmodels'

